<mujoco model="humanoid">
  <compiler coordinate="local" />
  <default>
    <joint damping="0.0" armature="0.01" stiffness="0.0" limited="true" />
    <geom conaffinity="1" condim="3" contype="7" margin="0.001" rgba="0.8 0.6 .4 1" />
  </default>
  <asset>
    <texture type="skybox" builtin="gradient" rgb1=".4 .5 .6" rgb2="0 0 0" width="100" height="100" />
    <texture builtin="flat" height="1278" mark="cross" markrgb="1 1 1" name="texgeom" random="0.01" rgb1="0.8 0.6 0.4" rgb2="0.8 0.6 0.4" type="cube" width="127" />
    <texture builtin="checker" height="100" name="texplane" rgb1="0 0 0" rgb2="0.8 0.8 0.8" type="2d" width="100" />
    <material name="MatPlane" reflectance="0.5" shininess="1" specular="1" texrepeat="60 60" texture="texplane" />
    <material name="geom" texture="texgeom" texuniform="true" />
  </asset>
  <worldbody>
    <light cutoff="100" diffuse="1 1 1" dir="-0 0 -1.3" directional="true" exponent="1" pos="0.000000 0.000000 1.300000" specular=".1 .1 .1" />
    <body name="Pelvis" pos="-0.001800 -0.223300 0.028200">
      <freejoint name="Pelvis" />
      <geom type="box" pos="-0.005500 -0.000000 -0.012100" size="0.083000 0.140000 0.072200" quat="1.0000 0.0000 0.0000 0.0000" density="1164.978473" />
      <body name="L_Hip" pos="-0.006550 0.095000 -0.091000">
        <joint name="L_Hip_x" type="hinge" pos="0.000000 0.000000 0.000000" axis="1 0 0" stiffness="250" damping="25" armature="0.02" range="-20.0000 45.0000" />
        <joint name="L_Hip_y" type="hinge" pos="0.000000 0.000000 0.000000" axis="0 1 0" stiffness="250" damping="25" armature="0.02" range="-30.0000 120.0000" />
        <joint name="L_Hip_z" type="hinge" pos="0.000000 0.000000 0.000000" axis="0 0 1" stiffness="250" damping="25" armature="0.02" range="-45.0000 45.0000" />
        <geom type="capsule" contype="1" conaffinity="1" density="4579.661072" fromto="0.000000 0.000000 -0.075000 0.000000 0.000000 -0.303000" size="0.060600" />
        <body name="L_Knee" pos="-0.006700 0.000000 -0.378900">
          <joint name="L_Knee_x" type="hinge" pos="0.000000 0.000000 0.000000" axis="1 0 0" stiffness="200" damping="20" armature="0.02" range="-10.0000 10.0000" />
          <joint name="L_Knee_y" type="hinge" pos="0.000000 0.000000 0.000000" axis="0 1 0" stiffness="200" damping="20" armature="0.02" range="-10.0000 150.0000" />
          <joint name="L_Knee_z" type="hinge" pos="0.000000 0.000000 0.000000" axis="0 0 1" stiffness="200" damping="20" armature="0.02" range="-15.0000 15.0000" />
          <geom type="capsule" contype="1" conaffinity="1" density="1624.381910" fromto="0.000000 0.000000 -0.079700 0.000000 0.000000 -0.318700" size="0.054100" />
          <body name="L_Ankle" pos="0.000000 0.000000 -0.398200">
            <joint name="L_Ankle_x" type="hinge" pos="0.000000 0.000000 0.000000" axis="1 0 0" stiffness="150" damping="15" armature="0.02" range="-10.0000 10.0000" />
            <joint name="L_Ankle_y" type="hinge" pos="0.000000 0.000000 0.000000" axis="0 1 0" stiffness="150" damping="15" armature="0.02" range="-45.0000 20.0000" />
            <joint name="L_Ankle_z" type="hinge" pos="0.000000 0.000000 0.000000" axis="0 0 1" stiffness="150" damping="15" armature="0.02" range="-10.0000 10.0000" />
            <geom type="box" pos="0.022500 0.000000 -0.020000" size="0.086500 0.040000 0.047800" quat="1.0000 0.0000 0.0000 0.0000" density="584.562194" />
            <body name="L_Toe" pos="0.123300 0.000000 -0.055000">
              <joint name="L_Toe_x" type="hinge" pos="0.000000 0.000000 0.000000" axis="1 0 0" stiffness="75" damping="8" armature="0.02" range="-10.0000 10.0000" />
              <joint name="L_Toe_y" type="hinge" pos="0.000000 0.000000 0.000000" axis="0 1 0" stiffness="75" damping="8" armature="0.02" range="-20.0000 20.0000" />
              <joint name="L_Toe_z" type="hinge" pos="0.000000 0.000000 0.000000" axis="0 0 1" stiffness="75" damping="8" armature="0.02" range="-5.0000 5.0000" />
              <geom type="box" pos="0.024800 0.000000 0.007000" size="0.049600 0.040000 0.020000" quat="1.0000 0.0000 0.0000 0.0000" density="584.562194" />
            </body>
          </body>
        </body>
      </body>
      <body name="R_Hip" pos="-0.006550 -0.095000 -0.091000">
        <joint name="R_Hip_x" type="hinge" pos="0.000000 0.000000 0.000000" axis="1 0 0" stiffness="250" damping="25" armature="0.02" range="-20.0000 45.0000" />
        <joint name="R_Hip_y" type="hinge" pos="0.000000 0.000000 0.000000" axis="0 1 0" stiffness="250" damping="25" armature="0.02" range="-30.0000 120.0000" />
        <joint name="R_Hip_z" type="hinge" pos="0.000000 0.000000 0.000000" axis="0 0 1" stiffness="250" damping="25" armature="0.02" range="-15.0000 15.0000" />
        <geom type="capsule" contype="1" conaffinity="1" density="4579.661072" fromto="0.000000 0.000000 -0.075000 0.000000 0.000000 -0.303000" size="0.060600" />
        <body name="R_Knee" pos="-0.006700 0.000000 -0.378900">
          <joint name="R_Knee_x" type="hinge" pos="0.000000 0.000000 0.000000" axis="1 0 0" stiffness="200" damping="20" armature="0.02" range="-10.0000 10.0000" />
          <joint name="R_Knee_y" type="hinge" pos="0.000000 0.000000 0.000000" axis="0 1 0" stiffness="200" damping="20" armature="0.02" range="-10.0000 150.0000" />
          <joint name="R_Knee_z" type="hinge" pos="0.000000 0.000000 0.000000" axis="0 0 1" stiffness="200" damping="20" armature="0.02" range="-15.0000 15.0000" />
          <geom type="capsule" contype="1" conaffinity="1" density="1624.381910" fromto="0.000000 0.000000 -0.079700 0.000000 0.000000 -0.318700" size="0.054100" />
          <body name="R_Ankle" pos="0.000000 0.000000 -0.398200">
            <joint name="R_Ankle_x" type="hinge" pos="0.000000 0.000000 0.000000" axis="1 0 0" stiffness="150" damping="15" armature="0.02" range="-25.0000 25.0000" />
            <joint name="R_Ankle_y" type="hinge" pos="0.000000 0.000000 0.000000" axis="0 1 0" stiffness="150" damping="15" armature="0.02" range="-45.0000 20.0000" />
            <joint name="R_Ankle_z" type="hinge" pos="0.000000 0.000000 0.000000" axis="0 0 1" stiffness="150" damping="15" armature="0.02" range="-10.0000 10.0000" />
            <geom type="box" pos="0.022500 0.000000 -0.020000" size="0.086500 0.040000 0.047800" quat="1.0000 0.0000 0.0000 0.0000" density="584.562194" />
            <body name="R_Toe" pos="0.123300 0.000000 -0.055000">
              <joint name="R_Toe_x" type="hinge" pos="0.000000 0.000000 0.000000" axis="1 0 0" stiffness="75" damping="8" armature="0.02" range="-10.0000 10.0000" />
              <joint name="R_Toe_y" type="hinge" pos="0.000000 0.000000 0.000000" axis="0 1 0" stiffness="75" damping="8" armature="0.02" range="-20.0000 20.0000" />
              <joint name="R_Toe_z" type="hinge" pos="0.000000 0.000000 0.000000" axis="0 0 1" stiffness="75" damping="8" armature="0.02" range="-5.0000 5.0000" />
              <geom type="box" pos="0.024800 0.000000 0.007000" size="0.049600 0.040000 0.020000" quat="1.0000 0.0000 0.0000 0.0000" density="584.562194" />
            </body>
          </body>
        </body>
      </body>
    </body>
  </worldbody>
  <actuator>
    <motor name="L_Hip_x" joint="L_Hip_x" gear="500" />
    <motor name="L_Hip_y" joint="L_Hip_y" gear="500" />
    <motor name="L_Hip_z" joint="L_Hip_z" gear="500" />
    <motor name="L_Knee_x" joint="L_Knee_x" gear="500" />
    <motor name="L_Knee_y" joint="L_Knee_y" gear="500" />
    <motor name="L_Knee_z" joint="L_Knee_z" gear="500" />
    <motor name="L_Ankle_x" joint="L_Ankle_x" gear="500" />
    <motor name="L_Ankle_y" joint="L_Ankle_y" gear="500" />
    <motor name="L_Ankle_z" joint="L_Ankle_z" gear="500" />
    <motor name="L_Toe_x" joint="L_Toe_x" gear="500" />
    <motor name="L_Toe_y" joint="L_Toe_y" gear="500" />
    <motor name="L_Toe_z" joint="L_Toe_z" gear="500" />
    <motor name="R_Hip_x" joint="R_Hip_x" gear="500" />
    <motor name="R_Hip_y" joint="R_Hip_y" gear="500" />
    <motor name="R_Hip_z" joint="R_Hip_z" gear="500" />
    <motor name="R_Knee_x" joint="R_Knee_x" gear="500" />
    <motor name="R_Knee_y" joint="R_Knee_y" gear="500" />
    <motor name="R_Knee_z" joint="R_Knee_z" gear="500" />
    <motor name="R_Ankle_x" joint="R_Ankle_x" gear="500" />
    <motor name="R_Ankle_y" joint="R_Ankle_y" gear="500" />
    <motor name="R_Ankle_z" joint="R_Ankle_z" gear="500" />
    <motor name="R_Toe_x" joint="R_Toe_x" gear="500" />
    <motor name="R_Toe_y" joint="R_Toe_y" gear="500" />
    <motor name="R_Toe_z" joint="R_Toe_z" gear="500" />
  </actuator>
</mujoco>